2023-01-31 16:58:57,446 INFO    StreamThr :20004 [internal.py:wandb_internal():87] W&B internal server running at pid: 20004, started at: 2023-01-31 16:58:57.445908
2023-01-31 16:58:57,448 DEBUG   HandlerThread:20004 [handler.py:handle_request():144] handle_request: status
2023-01-31 16:58:57,469 INFO    WriterThread:20004 [datastore.py:open_for_write():85] open: C:\Users\Abhinav\Desktop\RecSystem (1)\RecSystem\wandb\run-20230131_165857-ug1dwfxv\run-ug1dwfxv.wandb
2023-01-31 16:58:57,471 DEBUG   SenderThread:20004 [sender.py:send():334] send: header
2023-01-31 16:58:57,471 DEBUG   SenderThread:20004 [sender.py:send():334] send: run
2023-01-31 16:58:57,763 ERROR   SenderThread:20004 [internal_api.py:execute():244] 404 response executing GraphQL.
2023-01-31 16:58:57,763 ERROR   SenderThread:20004 [internal_api.py:execute():245] {"errors":[{"message":"entity YOUR_USERNAME not found during upsertBucket","path":["upsertBucket"]}],"data":{"upsertBucket":null}}
2023-01-31 16:58:58,474 INFO    WriterThread:20004 [datastore.py:close():299] close: C:\Users\Abhinav\Desktop\RecSystem (1)\RecSystem\wandb\run-20230131_165857-ug1dwfxv\run-ug1dwfxv.wandb
2023-01-31 16:58:58,474 INFO    HandlerThread:20004 [handler.py:finish():841] shutting down handler
2023-01-31 16:58:58,474 ERROR   StreamThr :20004 [internal.py:wandb_internal():175] Thread SenderThread:
Traceback (most recent call last):
  File "C:\dev\Python\lib\site-packages\wandb\sdk\lib\retry.py", line 128, in __call__
    result = self._call_fn(*args, **kwargs)
  File "C:\dev\Python\lib\site-packages\wandb\sdk\internal\internal_api.py", line 241, in execute
    return self.client.execute(*args, **kwargs)  # type: ignore
  File "C:\dev\Python\lib\site-packages\wandb\vendor\gql-0.2.0\wandb_gql\client.py", line 52, in execute
    result = self._get_result(document, *args, **kwargs)
  File "C:\dev\Python\lib\site-packages\wandb\vendor\gql-0.2.0\wandb_gql\client.py", line 60, in _get_result
    return self.transport.execute(document, *args, **kwargs)
  File "C:\dev\Python\lib\site-packages\wandb\vendor\gql-0.2.0\wandb_gql\transport\requests.py", line 39, in execute
    request.raise_for_status()
  File "C:\dev\Python\lib\site-packages\requests\models.py", line 1021, in raise_for_status
    raise HTTPError(http_error_msg, response=self)
requests.exceptions.HTTPError: 404 Client Error: Not Found for url: https://api.wandb.ai/graphql

During handling of the above exception, another exception occurred:

Traceback (most recent call last):
  File "C:\dev\Python\lib\site-packages\wandb\apis\normalize.py", line 26, in wrapper
    return func(*args, **kwargs)
  File "C:\dev\Python\lib\site-packages\wandb\sdk\internal\internal_api.py", line 1592, in upsert_run
    response = self.gql(
  File "C:\dev\Python\lib\site-packages\wandb\sdk\internal\internal_api.py", line 213, in gql
    ret = self._retry_gql(
  File "C:\dev\Python\lib\site-packages\wandb\sdk\lib\retry.py", line 144, in __call__
    retry_timedelta_triggered = check_retry_fn(e)
  File "C:\dev\Python\lib\site-packages\wandb\util.py", line 1065, in check_retry_fn
    return fallback_retry_fn(e)
  File "C:\dev\Python\lib\site-packages\wandb\util.py", line 1012, in no_retry_auth
    raise CommError("Permission denied, ask the project owner to grant you access")
wandb.errors.CommError: Permission denied, ask the project owner to grant you access

During handling of the above exception, another exception occurred:

Traceback (most recent call last):
  File "C:\dev\Python\lib\site-packages\wandb\sdk\internal\internal_util.py", line 49, in run
    self._run()
  File "C:\dev\Python\lib\site-packages\wandb\sdk\internal\internal_util.py", line 100, in _run
    self._process(record)
  File "C:\dev\Python\lib\site-packages\wandb\sdk\internal\internal.py", line 329, in _process
    self._sm.send(record)
  File "C:\dev\Python\lib\site-packages\wandb\sdk\internal\sender.py", line 341, in send
    send_handler(record)
  File "C:\dev\Python\lib\site-packages\wandb\sdk\internal\sender.py", line 927, in send_run
    self._init_run(run, config_value_dict)
  File "C:\dev\Python\lib\site-packages\wandb\sdk\internal\sender.py", line 955, in _init_run
    server_run, inserted, server_messages = self._api.upsert_run(
  File "C:\dev\Python\lib\site-packages\wandb\apis\normalize.py", line 64, in wrapper
    raise CommError(message, err).with_traceback(sys.exc_info()[2])
  File "C:\dev\Python\lib\site-packages\wandb\apis\normalize.py", line 26, in wrapper
    return func(*args, **kwargs)
  File "C:\dev\Python\lib\site-packages\wandb\sdk\internal\internal_api.py", line 1592, in upsert_run
    response = self.gql(
  File "C:\dev\Python\lib\site-packages\wandb\sdk\internal\internal_api.py", line 213, in gql
    ret = self._retry_gql(
  File "C:\dev\Python\lib\site-packages\wandb\sdk\lib\retry.py", line 144, in __call__
    retry_timedelta_triggered = check_retry_fn(e)
  File "C:\dev\Python\lib\site-packages\wandb\util.py", line 1065, in check_retry_fn
    return fallback_retry_fn(e)
  File "C:\dev\Python\lib\site-packages\wandb\util.py", line 1012, in no_retry_auth
    raise CommError("Permission denied, ask the project owner to grant you access")
wandb.errors.CommError: Permission denied, ask the project owner to grant you access
